<?xml version="1.0"?>
<robot xmlns:xacro="http://www.ros.org/wiki/xacro" name="multi">
    
    <material name="black">
        <color rgba="0 0 0 1"/>
    </material>
    
    <link name="base_link">
    <visual>
        <origin xyz="0 0 0" rpy="0 0 0" />
        <geometry>
        <box size="0.3 0.2 0.1"/>
        </geometry>
        <material name="black"/>
    </visual>
    <collision>
        <geometry>
        <box size="0.3 0.2 0.1"/>
        </geometry>
    </collision>
    <inertial>
        <mass value="1"/>
        <inertia ixx="1.75e-2" iyy="4.17e-3" izz="1.08e-2" ixy="0" ixz="0" iyz="0"/>
    </inertial>
    </link>

    <link name="left_front_wheel">
    <visual>
        <geometry>
        <cylinder length="0.02" radius="0.1"/>
        </geometry>
        <origin rpy="1.57075 0 0" xyz="0 0 0"/>
        <material name="black"/>
    </visual>
    <collision>
        <geometry>
        <cylinder length="0.02" radius="0.1"/>
        </geometry>
        <origin rpy="1.57075 0 0" xyz="0 0 0"/>
    </collision>
    <inertial>
        <mass value="0.1"/>
        <inertia ixx="2.53e-4" iyy="2.53e-4" izz="5e-4" ixy="0" ixz="0" iyz="0"/>
    </inertial>
    </link>

    <joint name="left_front_wheel_joint" type="continuous">
    <axis rpy="0 0 0" xyz="0 1 0"/>
    <parent link="base_link"/>
    <child link="left_front_wheel"/>
    <origin rpy="0 0 0" xyz="0.1 0.11 -0.02"/>
    </joint>

    <link name="right_front_wheel">
    <visual>
        <geometry>
        <cylinder length="0.02" radius="0.1"/>
        </geometry>
        <origin rpy="1.57075 0 0" xyz="0 0 0"/>
        <material name="black"/>
    </visual>
    <collision>
        <geometry>
        <cylinder length="0.02" radius="0.1"/>
        </geometry>
        <origin rpy="1.57075 0 0" xyz="0 0 0"/>
    </collision>
    <inertial>
        <mass value="0.1"/>
        <inertia ixx="2.53e-4" iyy="2.53e-4" izz="5e-4" ixy="0" ixz="0" iyz="0"/>
    </inertial>
    </link>

    <joint name="right_front_wheel_joint" type="continuous">
    <axis rpy="0 0 0" xyz="0 1 0"/>
    <parent link="base_link"/>
    <child link="right_front_wheel"/>
    <origin rpy="0 0 0" xyz="0.1 -0.11 -0.02"/>
    </joint>

    <link name="left_back_wheel">
    <visual>
        <geometry>
        <cylinder length="0.02" radius="0.1"/>
        </geometry>
        <origin rpy="1.57075 0 0" xyz="0 0 0"/>
        <material name="black"/>
    </visual>
    <collision>
        <geometry>
        <cylinder length="0.02" radius="0.1"/>
        </geometry>
        <origin rpy="1.57075 0 0" xyz="0 0 0"/>
    </collision>
    <inertial>
        <mass value="0.1"/>
        <inertia ixx="2.53e-4" iyy="2.53e-4" izz="5e-4" ixy="0" ixz="0" iyz="0"/>
    </inertial>
    </link>

    <joint name="left_back_wheel_joint" type="continuous">
    <axis rpy="0 0 0" xyz="0 1 0"/>
    <parent link="base_link"/>
    <child link="left_back_wheel"/>
    <origin rpy="0 0 0" xyz="-0.1 0.11 -0.02"/>
    </joint>

    <link name="right_back_wheel">
    <visual>
        <geometry>
        <cylinder length="0.02" radius="0.1"/>
        </geometry>
        <origin rpy="1.57075 0 0" xyz="0 0 0"/>
        <material name="black"/>
    </visual>
    <collision>
        <geometry>
        <cylinder length="0.02" radius="0.1"/>
        </geometry>
        <origin rpy="1.57075 0 0" xyz="0 0 0"/>
    </collision>
    <inertial>
        <mass value="0.1"/>
        <inertia ixx="2.53e-4" iyy="2.53e-4" izz="5e-4" ixy="0" ixz="0" iyz="0"/>
    </inertial>
    </link>

    <joint name="right_back_wheel_joint" type="continuous">
    <axis rpy="0 0 0" xyz="0 1 0"/>
    <parent link="base_link"/>
    <child link="right_back_wheel"/>
    <origin rpy="0 0 0" xyz="-0.1 -0.11 -0.02"/>
    </joint>

</robot>