<robot name="mobileagent">

  <material name="black">
    <color rgba="0 0 0 1"/>
  </material>

  <material name="white">
    <color rgba="1 1 1 1"/>
  </material>
  
  <link name="base_link">
    
  </link>
  
  <link name="chassis">
    <visual>
      <geometry>
        <box size="0.3 0.2 0.1"/>
      </geometry>
      <material name="white"/>
    </visual>
    <collision>
      <geometry>
        <box size="0.3 0.2 0.1"/>
      </geometry>
    </collision>
    <inertial>
      <mass value="1"/>
      <inertia ixx="1.75e-2" iyy="4.17e-3" izz="1.08e-2" ixy="0" ixz="0" iyz="0"/>
    </inertial>
  </link>

  <joint name="chassis_joint" type="fixed">
    <origin xyz="0 0 0.05" />
    <parent link="base_link"/>
    <child link="chassis"/>
  </joint>

  <link name="left_front_wheel">
    <visual>
      <geometry>
        <cylinder length="0.02" radius="0.05"/>
      </geometry>
      <material name="black"/>
    </visual>
    <collision>
      <geometry>
        <cylinder length="0.02" radius="0.05"/>
      </geometry>
      <origin rpy="1.57075 0 0" xyz="0 0 0"/>
    </collision>
    <inertial>
      <mass value="0.1"/>
      <inertia ixx="2.53e-4" iyy="2.53e-4" izz="5e-4" ixy="0" ixz="0" iyz="0"/>
    </inertial>
  </link>

  <joint name="left_front_wheel_joint" type="continuous">
    <axis xyz="0 0 1"/>
    <parent link="chassis"/>
    <child link="left_front_wheel"/>
    <origin rpy="1.57075 0 0" xyz="0.1 0.11 -0.02"/>
  </joint>

  <link name="right_front_wheel">
    <visual>
      <geometry>
        <cylinder length="0.02" radius="0.05"/>
      </geometry>
      <material name="black"/>
    </visual>
    <collision>
      <geometry>
        <cylinder length="0.02" radius="0.05"/>
      </geometry>
    </collision>
    <inertial>
      <mass value="0.1"/>
      <inertia ixx="2.53e-4" iyy="2.53e-4" izz="5e-4" ixy="0" ixz="0" iyz="0"/>
    </inertial>
  </link>

  <joint name="right_front_wheel_joint" type="continuous">
    <axis rpy="0 0 0" xyz="0 0 1"/>
    <parent link="chassis"/>
    <child link="right_front_wheel"/>
    <origin rpy="1.57075 0 0" xyz="0.1 -0.11 -0.02"/>
  </joint>

  <link name="left_back_wheel">
    <visual>
      <geometry>
        <cylinder length="0.02" radius="0.05"/>
      </geometry>
      <material name="black"/>
    </visual>
    <collision>
      <geometry>
        <cylinder length="0.02" radius="0.05"/>
      </geometry>
    </collision>
    <inertial>
      <mass value="0.1"/>
      <inertia ixx="2.53e-4" iyy="2.53e-4" izz="5e-4" ixy="0" ixz="0" iyz="0"/>
    </inertial>
  </link>

  <joint name="left_back_wheel_joint" type="continuous">
    <axis rpy="0 0 0" xyz="0 0 1"/>
    <parent link="chassis"/>
    <child link="left_back_wheel"/>
    <origin rpy="1.57075 0 0" xyz="-0.1 0.11 -0.02"/>
  </joint>

  <link name="right_back_wheel">
    <visual>
      <geometry>
        <cylinder length="0.02" radius="0.05"/>
      </geometry>
      <material name="black"/>
    </visual>
    <collision>
      <geometry>
        <cylinder length="0.02" radius="0.05"/>
      </geometry>
    </collision>
    <inertial>
      <mass value="0.1"/>
      <inertia ixx="2.53e-4" iyy="2.53e-4" izz="5e-4" ixy="0" ixz="0" iyz="0"/>
    </inertial>
  </link>

  <joint name="right_back_wheel_joint" type="continuous">
    <axis rpy="0 0 0" xyz="0 0 1"/>
    <parent link="chassis"/>
    <child link="right_back_wheel"/>
    <origin rpy="1.57075 0 0" xyz="-0.1 -0.11 -0.02"/>
  </joint>

</robot>
